<?xml version="1.0" ?>
<!-- =================================================================================== -->
<!-- |    This document was autogenerated by xacro from single_leg.urdf.xacro          | -->
<!-- |    EDITING THIS FILE BY HAND IS NOT RECOMMENDED                                 | -->
<!-- =================================================================================== -->
<robot name="single_leg" xmlns:xacro="http://www.ros.org/wiki/xacro">
  <!-- common stuff -->
  <gazebo>
    <plugin filename="libgazebo_ros_control.so" name="ros_control">
      <!--robotNamespace>/</robotNamespace-->
      <!--robotSimType>gazebo_ros_control/DefaultRobotHWSim</robotSimType-->
    </plugin>
    <plugin filename="libgazebo_ros_joint_state_publisher.so" name="joint_state_publisher">
      <!--robotNamespace>your_robot_name</robotNamespace-->
      <jointName>
          hip, knee
      </jointName>
      <updateRate>100</updateRate>
      <alwaysOn>true</alwaysOn>
    </plugin>
  </gazebo>
  <!--color define-->
  <gazebo reference="base_link">
    <material>Gazebo/Green</material>
  </gazebo>
  <gazebo reference="leg_base">
    <material>Gazebo/Turquoise</material>
  </gazebo>
  <gazebo reference="thigh">
    <material>Gazebo/Blue</material>
  </gazebo>
  <gazebo reference="shank">
    <material>Gazebo/Yellow</material>
  </gazebo>
  <gazebo reference="foot">
    <material>Gazebo/Red</material>
  </gazebo>
  <!-- single leg XACRO -->
  <!-- define transmission -->
  <!-- Inertia parameters -->
  <!-- link sizes -->
  <!-- The template for link -->
  <!-- The MACRO for single leg -->
  <link name="base_link">
    <visual>
      <geometry>
        <sphere radius="0.0001"/>
      </geometry>
      <origin rpy="0 0 0" xyz="0 0 0"/>
    </visual>
    <collision>
      <geometry>
        <sphere radius="0.0001"/>
      </geometry>
      <origin rpy="0 0 0" xyz="0 0 0"/>
    </collision>
    <inertial>
      <origin rpy="0 0 0" xyz="0 0 0"/>
      <mass value="0.0001"/>
      <inertia ixx="0" ixy="0.0" ixz="0.0" iyy="0" iyz="0.0" izz="0"/>
    </inertial>
  </link>
  <joint name="y_axis_joint" type="fixed">
    <parent link="base_link"/>
    <child link="framework"/>
    <origin rpy="0.0 0.0 0.0" xyz="0.0 0.0 0"/>
  </joint>
  <link name="framework">
    <visual>
      <geometry>
        <mesh filename="package://dragon_description/meshes/main1m.stl"/>
      </geometry>
      <origin rpy="0 1.570796325 0" xyz="0 0 0"/>
    </visual>
    <collision>
      <geometry>
        <mesh filename="package://dragon_description/meshes/main1m.stl"/>
      </geometry>
      <origin rpy="0 1.570796325 0" xyz="0 0 0"/>
    </collision>
    <inertial>
      <origin rpy="0 0 0" xyz="0 0 0"/>
      <mass value="0"/>
      <inertia ixx="0" ixy="0" ixz="0" iyy="0" iyz="0" izz="0"/>
    </inertial>
  </link>
  <!--xacro:link_template name="y_axis">
    <box size="0.01 0.02 5"/>
    <origin xyz="0 -0.04 0" rpy="0 ${pi/2} 0" />
    <inertial>
      <origin xyz="0 0 0" rpy="0 0 0" />
      <mass value="0"/>
      <inertia ixx="0" ixy="0.0" ixz="0.0" iyy="0" iyz="0.0" izz="0"/>
    </inertial>
  </xacro:link_template-->
  <joint name="z_axis_joint" type="prismatic">
    <parent link="framework"/>
    <child link="z_axis"/>
    <origin rpy="0.0 0.0 0.0" xyz="0.0 0.0 0.0"/>
    <limit effort="100" lower="-2.5" upper="2.5" velocity="100"/>
    <axis xyz="1 0 0"/>
  </joint>
  <link name="z_axis">
    <visual>
      <geometry>
        <mesh filename="package://dragon_description/meshes/main2m.stl"/>
      </geometry>
      <origin rpy="1.570796325 0 0" xyz="0 0 0"/>
    </visual>
    <collision>
      <geometry>
        <mesh filename="package://dragon_description/meshes/main2m.stl"/>
      </geometry>
      <origin rpy="1.570796325 0 0" xyz="0 0 0"/>
    </collision>
    <inertial>
      <origin rpy="0 0 0" xyz="0 0 0"/>
      <mass value="0"/>
      <inertia ixx="0" ixy="0" ixz="0" iyy="0" iyz="0" izz="0"/>
    </inertial>
  </link>
  <!--xacro:link_template name="z_axis">
    <box size="0.01 0.02 3"/>
    <origin xyz="0.1 -0.03 1.2" rpy="0 0 ${pi/2}" />
    <inertial>
      <origin xyz="0 0 0" rpy="0 0 0" />
      <mass value="0.0001"/>
      <inertia ixx="0" ixy="0.0" ixz="0.0" iyy="0" iyz="0.0" izz="0"/>
    </inertial>
  </xacro:link_template-->
  <joint name="axis_to_base_joint" type="prismatic">
    <parent link="z_axis"/>
    <child link="leg_base"/>
    <origin rpy="0.0 0.0 0.0" xyz="0.0 0.0 0.0"/>
    <limit effort="100" lower="-0.2" upper="1.5" velocity="100"/>
    <axis xyz="0 0 1"/>
  </joint>
  <!-- single leg -->
  <link name="leg_base">
    <visual>
      <geometry>
        <mesh filename="package://dragon_description/meshes/body_part.stl"/>
      </geometry>
      <origin rpy="1.570796325 0 0" xyz="0 0 0"/>
    </visual>
    <collision>
      <geometry>
        <mesh filename="package://dragon_description/meshes/body_part.stl"/>
      </geometry>
      <origin rpy="1.570796325 0 0" xyz="0 0 0"/>
    </collision>
    <inertial>
      <origin rpy="0 0 0" xyz="0 0 0"/>
      <mass value="0.67833686"/>
      <inertia ixx="0.00038117398" ixy="0" ixz="0" iyy="0.0064911269" iyz="0" izz="0.0066170081"/>
    </inertial>
  </link>
  <joint name="hip" type="revolute">
    <parent link="leg_base"/>
    <child link="thigh"/>
    <axis xyz="0 1 0"/>
    <origin rpy="0 0 0" xyz="0 0 0"/>
    <dynamics damping="0" friction="0"/>
    <limit effort="100" lower="-0.62831853" upper="-0.01570796325" velocity="100"/>
  </joint>
  <link name="thigh">
    <visual>
      <geometry>
        <mesh filename="package://dragon_description/meshes/upper_leg.stl"/>
      </geometry>
      <origin rpy="1.570796325 0 0" xyz="0 0 0"/>
    </visual>
    <collision>
      <geometry>
        <mesh filename="package://dragon_description/meshes/upper_leg.stl"/>
      </geometry>
      <origin rpy="1.570796325 0 0" xyz="0 0 0"/>
    </collision>
    <inertial>
      <origin rpy="0 0 0" xyz="0 0 0"/>
      <mass value="0.58240446"/>
      <inertia ixx="0.0055694595" ixy="0" ixz="0" iyy="0.0055169487" iyz="0" izz="0.00024018505"/>
    </inertial>
  </link>
  <joint name="knee" type="revolute">
    <parent link="thigh"/>
    <child link="shank"/>
    <axis xyz="0 1 0"/>
    <origin rpy="0 0 0" xyz="0 0 -0.275"/>
    <dynamics damping="0" friction="0"/>
    <!--limit lower="0.174532922" upper="1.919862144" effort="100" velocity="100"/-->
    <limit effort="100" lower="-0.01570796325" upper="0.942477795" velocity="100"/>
  </joint>
  <link name="shank">
    <visual>
      <geometry>
        <mesh filename="package://dragon_description/meshes/back_shine.stl"/>
      </geometry>
      <origin rpy="0 0 1.570796325" xyz="0 0 0"/>
    </visual>
    <collision>
      <geometry>
        <mesh filename="package://dragon_description/meshes/back_shine.stl"/>
      </geometry>
      <origin rpy="0 0 1.570796325" xyz="0 0 0"/>
    </collision>
    <inertial>
      <origin rpy="0 0 0" xyz="0 0 0"/>
      <mass value="0.29186134"/>
      <inertia ixx="0.0013222921" ixy="0" ixz="0" iyy="0.000039937780" iyz="0" izz="0.0013349732"/>
    </inertial>
  </link>
  <joint name="ankle" type="fixed">
    <parent link="shank"/>
    <child link="foot"/>
    <origin rpy="0 0 0" xyz="0 0 -0.266"/>
  </joint>
  <link name="foot">
    <visual>
      <geometry>
        <sphere radius="0.01"/>
      </geometry>
      <origin rpy="0 0 0" xyz="0 0 0"/>
    </visual>
    <collision>
      <geometry>
        <sphere radius="0.01"/>
      </geometry>
      <origin rpy="0 0 0" xyz="0 0 0"/>
    </collision>
    <inertial>
      <origin rpy="0 0 0" xyz="0 0 0"/>
      <mass value="0.01"/>
      <inertia ixx="0.000004" ixy="0.0" ixz="0.0" iyy="0.000004" iyz="0.0" izz="0.000004"/>
    </inertial>
  </link>
  <!-- Define transmission for the leg, MUST BE Set the hardwareInterface -->
  <transmission name="hip_trans">
    <type>transmission_interface/SimpleTransmission</type>
    <joint name="hip">
      <hardwareInterface>EffortJointInterface</hardwareInterface>
    </joint>
    <actuator name="hip_motor">
      <mechanicalReduction>1</mechanicalReduction>
    </actuator>
  </transmission>
  <transmission name="knee_trans">
    <type>transmission_interface/SimpleTransmission</type>
    <joint name="knee">
      <hardwareInterface>EffortJointInterface</hardwareInterface>
    </joint>
    <actuator name="knee_motor">
      <mechanicalReduction>1</mechanicalReduction>
    </actuator>
  </transmission>
</robot>

