<?xml version="1.0" ?>
<!-- =================================================================================== -->
<!-- |    This document was autogenerated by xacro from single_leg.urdf.xacro          | -->
<!-- |    EDITING THIS FILE BY HAND IS NOT RECOMMENDED                                 | -->
<!-- =================================================================================== -->
<robot name="single_leg" xmlns:xacro="http://www.ros.org/wiki/xacro">
  <!-- common stuff -->
  <gazebo>
    <plugin filename="libgazebo_ros_control.so" name="ros_control">
      <!--robotNamespace>/</robotNamespace-->
      <!--robotSimType>gazebo_ros_control/DefaultRobotHWSim</robotSimType-->
    </plugin>
  </gazebo>
  <!-- single leg XACRO -->
  <!-- define transmission -->
  <!-- Inertia parameters -->
  <!-- link sizes -->
  <!-- The template for link -->
  <!-- The MACRO for single leg -->
  <link name="world"/>
  <joint name="world_to_base_link_joint" type="fixed">
    <parent link="world"/>
    <child link="base_link"/>
  </joint>
  <link name="base_link">
    <visual>
      <geometry>
        <sphere radius="0.0001"/>
      </geometry>
      <origin rpy="0 0 0" xyz="0 0 0"/>
    </visual>
    <collision>
      <geometry>
        <sphere radius="0.0001"/>
      </geometry>
      <origin rpy="0 0 0" xyz="0 0 0"/>
    </collision>
    <inertial>
      <origin rpy="0 0 0" xyz="0 0 0"/>
      <mass value="0.0001"/>
      <inertia ixx="0" ixy="0.0" ixz="0.0" iyy="0" iyz="0.0" izz="0"/>
    </inertial>
  </link>
  <!-- single leg -->
  <link name="leg_base">
    <visual>
      <geometry>
        <mesh filename="package://dragon_description/meshes/body_part.stl"/>
      </geometry>
      <origin rpy="1.570796325 0 0" xyz="0 0 0"/>
    </visual>
    <collision>
      <geometry>
        <mesh filename="package://dragon_description/meshes/body_part.stl"/>
      </geometry>
      <origin rpy="1.570796325 0 0" xyz="0 0 0"/>
    </collision>
    <inertial>
      <origin rpy="0 0 0" xyz="0 0 0"/>
      <mass value="0.67833686"/>
      <inertia ixx="0.00038117398" ixy="0" ixz="0" iyy="0.0064911269" iyz="0" izz="0.0066170081"/>
    </inertial>
  </link>
  <joint name="hip" type="revolute">
    <parent link="leg_base"/>
    <child link="thigh"/>
    <axis xyz="0 1 0"/>
    <origin rpy="0 0 0" xyz="0 0 0"/>
    <dynamics damping="0" friction="0"/>
    <!--limit lower="-0.78539815" upper="0.698131689" effort="100" velocity="100"/-->
    <limit effort="100" lower="-0.62831853" upper="-0.01570796325" velocity="100"/>
  </joint>
  <link name="thigh">
    <visual>
      <geometry>
        <mesh filename="package://dragon_description/meshes/upper_leg.stl"/>
      </geometry>
      <origin rpy="1.570796325 0 0" xyz="0 0 0"/>
    </visual>
    <collision>
      <geometry>
        <mesh filename="package://dragon_description/meshes/upper_leg.stl"/>
      </geometry>
      <origin rpy="1.570796325 0 0" xyz="0 0 0"/>
    </collision>
    <inertial>
      <origin rpy="0 0 0" xyz="0 0 0"/>
      <mass value="0.58240446"/>
      <inertia ixx="0.0055694595" ixy="0" ixz="0" iyy="0.0055169487" iyz="0" izz="0.00024018505"/>
    </inertial>
  </link>
  <joint name="knee" type="revolute">
    <parent link="thigh"/>
    <child link="shank"/>
    <axis xyz="0 1 0"/>
    <origin rpy="0 0 0" xyz="0 0 -0.275"/>
    <dynamics damping="0" friction="0"/>
    <!--limit lower="0.174532922" upper="1.919862144" effort="100" velocity="100"/-->
    <limit effort="100" lower="-0.01570796325" upper="0.942477795" velocity="100"/>
  </joint>
  <link name="shank">
    <visual>
      <geometry>
        <mesh filename="package://dragon_description/meshes/back_shine.stl"/>
      </geometry>
      <origin rpy="0 0 1.570796325" xyz="0 0 0"/>
    </visual>
    <collision>
      <geometry>
        <mesh filename="package://dragon_description/meshes/back_shine.stl"/>
      </geometry>
      <origin rpy="0 0 1.570796325" xyz="0 0 0"/>
    </collision>
    <inertial>
      <origin rpy="0 0 0" xyz="0 0 0"/>
      <mass value="0.29186134"/>
      <inertia ixx="0.0013222921" ixy="0" ixz="0" iyy="0.000039937780" iyz="0" izz="0.0013349732"/>
    </inertial>
  </link>
  <joint name="ankle" type="fixed">
    <parent link="shank"/>
    <child link="foot"/>
    <origin rpy="0 0 0" xyz="0 0 -0.266"/>
  </joint>
  <link name="foot">
    <visual>
      <geometry>
        <sphere radius="0.01"/>
      </geometry>
      <origin rpy="0 0 0" xyz="0 0 0"/>
    </visual>
    <collision>
      <geometry>
        <sphere radius="0.01"/>
      </geometry>
      <origin rpy="0 0 0" xyz="0 0 0"/>
    </collision>
    <inertial>
      <origin rpy="0 0 0" xyz="0 0 0"/>
      <mass value="0.01"/>
      <inertia ixx="0.000004" ixy="0.0" ixz="0.0" iyy="0.000004" iyz="0.0" izz="0.000004"/>
    </inertial>
  </link>
  
  <!-- Define transmission for the leg, MUST BE Set the hardwareInterface -->
  <transmission name="hip_trans">
    <type>transmission_interface/SimpleTransmission</type>
    <joint name="hip">
      <hardwareInterface>EffortJointInterface</hardwareInterface>
    </joint>
    <actuator name="hip_motor">
      <mechanicalReduction>1</mechanicalReduction>
    </actuator>
  </transmission>
  <transmission name="knee_trans">
    <type>transmission_interface/SimpleTransmission</type>
    <joint name="knee">
      <hardwareInterface>EffortJointInterface</hardwareInterface>
    </joint>
    <actuator name="knee_motor">
      <mechanicalReduction>1</mechanicalReduction>
    </actuator>
  </transmission>
  <!-- The joint between the base of single leg and the world -->
  <joint name="base_link_to_base_joint" type="prismatic">
    <parent link="base_link"/>
    <child link="leg_base"/>
    <origin rpy="0.0 0.0 0.0" xyz="0.0 0.0 0.7"/>
    <limit effort="100" lower="-0.7" upper="1.0" velocity="100"/>
    <axis xyz="0 0 1"/>
  </joint>
</robot>
